2022-03-04 21:21:47,857 ERROR: Exception on /download_table/1 [GET] [in C:\Users\62821\belajar_python\flask\env\lib\site-packages\flask\app.py:1457]
Traceback (most recent call last):
  File "C:\Users\62821\belajar_python\flask\env\lib\site-packages\flask\app.py", line 2073, in wsgi_app
    response = self.full_dispatch_request()
  File "C:\Users\62821\belajar_python\flask\env\lib\site-packages\flask\app.py", line 1518, in full_dispatch_request
    rv = self.handle_user_exception(e)
  File "C:\Users\62821\belajar_python\flask\env\lib\site-packages\flask\app.py", line 1516, in full_dispatch_request
    rv = self.dispatch_request()
  File "C:\Users\62821\belajar_python\flask\env\lib\site-packages\flask\app.py", line 1502, in dispatch_request
    return self.ensure_sync(self.view_functions[rule.endpoint])(**req.view_args)
  File "C:\Users\62821\Documents\GitHub\4p-flask\app\routes.py", line 330, in download_table
    return excel.make_response_from_query_sets(user, query_sets, column_names, "xlsx")
  File "C:\Users\62821\belajar_python\flask\env\lib\site-packages\pyexcel_webio\__init__.py", line 434, in make_response_from_query_sets
    file_stream = pe.save_as(query_sets=query_sets, column_names=column_names,
  File "C:\Users\62821\belajar_python\flask\env\lib\site-packages\pyexcel\core.py", line 77, in save_as
    sheet_stream = sources.get_sheet_stream(**source_keywords)
  File "C:\Users\62821\belajar_python\flask\env\lib\site-packages\pyexcel\internal\core.py", line 21, in get_sheet_stream
    sheets = a_source.get_data()
  File "C:\Users\62821\belajar_python\flask\env\lib\site-packages\pyexcel\plugins\sources\querysets.py", line 72, in get_data
    data = get_data(
  File "C:\Users\62821\belajar_python\flask\env\lib\site-packages\pyexcel_io\io.py", line 86, in get_data
    data, _ = _get_data(
  File "C:\Users\62821\belajar_python\flask\env\lib\site-packages\pyexcel_io\io.py", line 105, in _get_data
    return load_data(**keywords)
  File "C:\Users\62821\belajar_python\flask\env\lib\site-packages\pyexcel_io\io.py", line 208, in load_data
    result[key] = list(result[key])
  File "C:\Users\62821\belajar_python\flask\env\lib\site-packages\pyexcel_io\sheet.py", line 55, in to_array
    for row_index, row in enumerate(self.row_iterator()):
  File "C:\Users\62821\belajar_python\flask\env\lib\site-packages\pyexcel_io\reader.py", line 123, in row_iterator
    yield from self._native_sheet.row_iterator()
TypeError: 'User' object is not iterable
2022-03-04 21:23:18,394 INFO: Blog startup [in C:\Users\62821\Documents\GitHub\4p-flask\app\__init__.py:54]
2022-03-04 21:23:21,109 ERROR: Exception on /download_table/1 [GET] [in C:\Users\62821\belajar_python\flask\env\lib\site-packages\flask\app.py:1457]
Traceback (most recent call last):
  File "C:\Users\62821\belajar_python\flask\env\lib\site-packages\flask\app.py", line 2073, in wsgi_app
    response = self.full_dispatch_request()
  File "C:\Users\62821\belajar_python\flask\env\lib\site-packages\flask\app.py", line 1518, in full_dispatch_request
    rv = self.handle_user_exception(e)
  File "C:\Users\62821\belajar_python\flask\env\lib\site-packages\flask\app.py", line 1516, in full_dispatch_request
    rv = self.dispatch_request()
  File "C:\Users\62821\belajar_python\flask\env\lib\site-packages\flask\app.py", line 1502, in dispatch_request
    return self.ensure_sync(self.view_functions[rule.endpoint])(**req.view_args)
  File "C:\Users\62821\Documents\GitHub\4p-flask\app\routes.py", line 327, in download_table
    query_sets = user.data.all()
AttributeError: 'User' object has no attribute 'data'
2022-03-04 21:24:20,147 INFO: Blog startup [in C:\Users\62821\Documents\GitHub\4p-flask\app\__init__.py:54]
2022-03-04 21:24:21,762 ERROR: Exception on /download_table/1 [GET] [in C:\Users\62821\belajar_python\flask\env\lib\site-packages\flask\app.py:1457]
Traceback (most recent call last):
  File "C:\Users\62821\belajar_python\flask\env\lib\site-packages\flask\app.py", line 2073, in wsgi_app
    response = self.full_dispatch_request()
  File "C:\Users\62821\belajar_python\flask\env\lib\site-packages\flask\app.py", line 1518, in full_dispatch_request
    rv = self.handle_user_exception(e)
  File "C:\Users\62821\belajar_python\flask\env\lib\site-packages\flask\app.py", line 1516, in full_dispatch_request
    rv = self.dispatch_request()
  File "C:\Users\62821\belajar_python\flask\env\lib\site-packages\flask\app.py", line 1502, in dispatch_request
    return self.ensure_sync(self.view_functions[rule.endpoint])(**req.view_args)
  File "C:\Users\62821\Documents\GitHub\4p-flask\app\routes.py", line 329, in download_table
    return excel.make_response_from_query_sets(query_sets, column_names, "xlsx")
  File "C:\Users\62821\belajar_python\flask\env\lib\site-packages\pyexcel_webio\__init__.py", line 434, in make_response_from_query_sets
    file_stream = pe.save_as(query_sets=query_sets, column_names=column_names,
  File "C:\Users\62821\belajar_python\flask\env\lib\site-packages\pyexcel\core.py", line 77, in save_as
    sheet_stream = sources.get_sheet_stream(**source_keywords)
  File "C:\Users\62821\belajar_python\flask\env\lib\site-packages\pyexcel\internal\core.py", line 21, in get_sheet_stream
    sheets = a_source.get_data()
  File "C:\Users\62821\belajar_python\flask\env\lib\site-packages\pyexcel\plugins\sources\querysets.py", line 72, in get_data
    data = get_data(
  File "C:\Users\62821\belajar_python\flask\env\lib\site-packages\pyexcel_io\io.py", line 86, in get_data
    data, _ = _get_data(
  File "C:\Users\62821\belajar_python\flask\env\lib\site-packages\pyexcel_io\io.py", line 105, in _get_data
    return load_data(**keywords)
  File "C:\Users\62821\belajar_python\flask\env\lib\site-packages\pyexcel_io\io.py", line 208, in load_data
    result[key] = list(result[key])
  File "C:\Users\62821\belajar_python\flask\env\lib\site-packages\pyexcel_io\sheet.py", line 55, in to_array
    for row_index, row in enumerate(self.row_iterator()):
  File "C:\Users\62821\belajar_python\flask\env\lib\site-packages\pyexcel_io\reader.py", line 123, in row_iterator
    yield from self._native_sheet.row_iterator()
TypeError: 'User' object is not iterable
2022-03-04 21:25:33,454 INFO: Blog startup [in C:\Users\62821\Documents\GitHub\4p-flask\app\__init__.py:54]
2022-03-04 21:25:38,176 ERROR: Exception on /download_table/1 [GET] [in C:\Users\62821\belajar_python\flask\env\lib\site-packages\flask\app.py:1457]
Traceback (most recent call last):
  File "C:\Users\62821\belajar_python\flask\env\lib\site-packages\flask\app.py", line 2073, in wsgi_app
    response = self.full_dispatch_request()
  File "C:\Users\62821\belajar_python\flask\env\lib\site-packages\flask\app.py", line 1518, in full_dispatch_request
    rv = self.handle_user_exception(e)
  File "C:\Users\62821\belajar_python\flask\env\lib\site-packages\flask\app.py", line 1516, in full_dispatch_request
    rv = self.dispatch_request()
  File "C:\Users\62821\belajar_python\flask\env\lib\site-packages\flask\app.py", line 1502, in dispatch_request
    return self.ensure_sync(self.view_functions[rule.endpoint])(**req.view_args)
  File "C:\Users\62821\Documents\GitHub\4p-flask\app\routes.py", line 329, in download_table
    return excel.make_response_from_query_sets(query_sets, column_names, "xlsx")
  File "C:\Users\62821\belajar_python\flask\env\lib\site-packages\pyexcel_webio\__init__.py", line 434, in make_response_from_query_sets
    file_stream = pe.save_as(query_sets=query_sets, column_names=column_names,
  File "C:\Users\62821\belajar_python\flask\env\lib\site-packages\pyexcel\core.py", line 77, in save_as
    sheet_stream = sources.get_sheet_stream(**source_keywords)
  File "C:\Users\62821\belajar_python\flask\env\lib\site-packages\pyexcel\internal\core.py", line 21, in get_sheet_stream
    sheets = a_source.get_data()
  File "C:\Users\62821\belajar_python\flask\env\lib\site-packages\pyexcel\plugins\sources\querysets.py", line 72, in get_data
    data = get_data(
  File "C:\Users\62821\belajar_python\flask\env\lib\site-packages\pyexcel_io\io.py", line 86, in get_data
    data, _ = _get_data(
  File "C:\Users\62821\belajar_python\flask\env\lib\site-packages\pyexcel_io\io.py", line 105, in _get_data
    return load_data(**keywords)
  File "C:\Users\62821\belajar_python\flask\env\lib\site-packages\pyexcel_io\io.py", line 208, in load_data
    result[key] = list(result[key])
  File "C:\Users\62821\belajar_python\flask\env\lib\site-packages\pyexcel_io\sheet.py", line 55, in to_array
    for row_index, row in enumerate(self.row_iterator()):
  File "C:\Users\62821\belajar_python\flask\env\lib\site-packages\pyexcel_io\reader.py", line 123, in row_iterator
    yield from self._native_sheet.row_iterator()
TypeError: 'User' object is not iterable
2022-03-04 21:27:58,323 INFO: Blog startup [in C:\Users\62821\Documents\GitHub\4p-flask\app\__init__.py:54]
2022-03-04 21:31:35,538 INFO: Blog startup [in C:\Users\62821\Documents\GitHub\4p-flask\app\__init__.py:54]
